<?xml version="1.0" encoding="UTF-8"?>
<robot xmlns:xacro="http://www.ros.org/wiki/xacro">
    
    <xacro:include filename="consts.xacro" /> 

    <!-- Joint Limits -->
    <xacro:macro name="bl_to_coxa_limits">
    <limit upper="1.658063" lower="-0.523599" velocity="${velocity}" effort="${effort}"/> <!-- effort = 7 -->
    </xacro:macro>
    <xacro:macro name="coxa_to_femur_limits">
    <limit upper="0.087266" lower="-2.70526" velocity="${velocity}" effort="${effort}"/>
    </xacro:macro>
    <xacro:macro name="femur_to_tibia_limits">
    <limit upper="0.087266" lower="-2.70526" velocity="${velocity}" effort="${effort}"/>
    </xacro:macro>

    <joint name="bf_to_bl" type="fixed">
      <child link="base_footprint"/>
      <parent link="base_link"/>
      <origin xyz="0.0 0.0 0.0" rpy="0.0 0.0 0.0"/>
    </joint>
  

    <joint name="right_wheel_joint" type="continuous">
        <origin xyz="-0.00046 -0.082929 0.049" rpy="0 0 0"/>
        <parent link="base_link"/>
        <child link="right_wheel_1"/>
        <axis xyz="0.0 1.0 0.0"/>
      </joint>

      <joint name="left_wheel_joint" type="continuous">
        <origin xyz="-0.00046 0.08385 0.049" rpy="0 0 0"/>
        <parent link="base_link"/>
        <child link="left_wheel_1"/>
        <axis xyz="0.0 1.0 0.0"/>
      </joint>

      <joint name="castor_back_joint" type="fixed">
        <origin xyz="-0.085732 0.00046 0.028" rpy="0 0 0"/>
        <parent link="base_link"/>
        <child link="caster_back_1"/>
      </joint>

      <joint name="castor_front_joint" type="fixed">
        <origin xyz="0.085732 0.00046 0.028" rpy="0 0 0"/>
        <parent link="base_link"/>
        <child link="caster_front_1"/>
      </joint>
      
      <joint name="lidar_joint" type="fixed">
        <origin xyz="0.070405 0.001718 0.091239" rpy="0 0 0"/>
        <parent link="base_link"/>
        <child link="lidar_1"/>
      </joint>
      
      <!-- <joint name="fr_sensor_to_tibia" type="fixed">
        <origin xyz="0.048829 -0.012342 -0.115032" rpy="0 0 0"/>
        <parent link="fr_tibia_1"/>
        <child link="fr_sensor_1"/>
      </joint>
      
      <joint name="fr_tibia_to_femur" type="revolute">
        <origin xyz="-1e-06 -1e-06 0.08" rpy="0 0 0"/>
        <parent link="fr_femur_1"/>
        <child link="fr_tibia_1"/>
        <axis xyz="-0.0 1.0 0.0"/>
        <xacro:femur_to_tibia_limits></xacro:femur_to_tibia_limits>
        <xacro:joint_dynamics></xacro:joint_dynamics>
      </joint>
      
      <joint name="fr_femur_to_coxa" type="revolute">
        <origin xyz="0.012509 -0.048995 0.0185" rpy="0 0 0"/>
        <parent link="fr_coxa_1"/>
        <child link="fr_femur_1"/>
        <axis xyz="0.0 -1.0 0.0"/>
        <xacro:coxa_to_femur_limits></xacro:coxa_to_femur_limits>
        <xacro:joint_dynamics></xacro:joint_dynamics>
      </joint>
      
      <joint name="fr_coxa_to_baselink" type="revolute">
        <origin xyz="0.091978 -0.082887 0.0409" rpy="0 0 0"/>
        <parent link="base_link"/>
        <child link="fr_coxa_1"/>
        <axis xyz="-0.0 -0.0 -1.0"/>
        <xacro:bl_to_coxa_limits></xacro:bl_to_coxa_limits>
        <xacro:joint_dynamics></xacro:joint_dynamics>
      </joint>
      
      <joint name="fl_sensor_to_tibia" type="fixed">
        <origin xyz="0.048829 0.012342 -0.115032" rpy="0 0 0"/>
        <parent link="fl_tibia_1"/>
        <child link="fl_sensor_1"/>
      </joint>
      
      <joint name="fl_tibia_to_femur" type="revolute">
        <origin xyz="-1e-06 1e-06 0.08" rpy="0 0 0"/>
        <parent link="fl_femur_1"/>
        <child link="fl_tibia_1"/>
        <axis xyz="0.0 1.0 0.0"/>
        <xacro:femur_to_tibia_limits></xacro:femur_to_tibia_limits>
        <xacro:joint_dynamics></xacro:joint_dynamics>
      </joint>
      
      <joint name="fl_femur_to_coxa" type="revolute">
        <origin xyz="0.012509 0.048995 0.0185" rpy="0 0 0"/>
        <parent link="fl_coxa_1"/>
        <child link="fl_femur_1"/>
        <axis xyz="-0.0 -1.0 -0.0"/>
        <xacro:coxa_to_femur_limits></xacro:coxa_to_femur_limits>
        <xacro:joint_dynamics></xacro:joint_dynamics>
      </joint>
      
      <joint name="fl_coxa_to_baselink" type="revolute">
        <origin xyz="0.091978 0.082887 0.0409" rpy="0 0 0"/>
        <parent link="base_link"/>
        <child link="fl_coxa_1"/>
        <axis xyz="0.0 -0.0 1.0"/>
        <xacro:bl_to_coxa_limits></xacro:bl_to_coxa_limits>
        <xacro:joint_dynamics></xacro:joint_dynamics>
      </joint>
      
      <joint name="rr_sensor_to_tibia" type="fixed">
        <origin xyz="-0.048829 -0.012342 -0.115032" rpy="0 0 0"/>
        <parent link="rr_tibia_1"/>
        <child link="rr_sensor_1"/>
      </joint>
      
      <joint name="rr_tibia_to_femur" type="revolute">
        <origin xyz="1e-06 -1e-06 0.08" rpy="0 0 0"/>
        <parent link="rr_femur_1"/>
        <child link="rr_tibia_1"/>
        <axis xyz="-0.0 -1.0 0.0"/>
        <xacro:femur_to_tibia_limits></xacro:femur_to_tibia_limits>
        <xacro:joint_dynamics></xacro:joint_dynamics>
      </joint>
      
      <joint name="rr_femur_to_coxa" type="revolute">
         <origin xyz="-0.012509 -0.048995 0.0185" rpy="0 0 0"/>
        <parent link="rr_coxa_1"/>
        <child link="rr_femur_1"/>
        <axis xyz="0.0 1.0 -0.0"/>
        <xacro:coxa_to_femur_limits></xacro:coxa_to_femur_limits>
        <xacro:joint_dynamics></xacro:joint_dynamics>
      </joint>
      
      <joint name="rr_coxa_to_baselink" type="revolute">
        <origin xyz="-0.091978 -0.082887 0.0409" rpy="0 0 0"/>
        <parent link="base_link"/>
        <child link="rr_coxa_1"/>
        <axis xyz="-0.0 0.0 1.0"/>
        <xacro:bl_to_coxa_limits></xacro:bl_to_coxa_limits>
        <xacro:joint_dynamics></xacro:joint_dynamics>
      </joint>
      
      <joint name="rl_sensor_to_tibia" type="fixed">
         <origin xyz="-0.048829 0.012342 -0.115032" rpy="0 0 0"/>
        <parent link="rl_tibia_1"/>
        <child link="rl_sensor_1"/>
      </joint>
      
      <joint name="rl_tibia_to_femur" type="revolute">
        <origin xyz="1e-06 1e-06 0.08" rpy="0 0 0"/>
        <parent link="rl_femur_1"/>
        <child link="rl_tibia_1"/>
        <axis xyz="0.0 -1.0 -0.0"/>
        <xacro:femur_to_tibia_limits></xacro:femur_to_tibia_limits>
        <xacro:joint_dynamics></xacro:joint_dynamics>
      </joint>
      
      <joint name="rl_femur_to_coxa" type="revolute">
        <origin xyz="-0.012509 0.048995 0.0185" rpy="0 0 0"/>
        <parent link="rl_coxa_1"/>
        <child link="rl_femur_1"/>
        <axis xyz="-0.0 1.0 0.0"/>
        <xacro:coxa_to_femur_limits></xacro:coxa_to_femur_limits>
        <xacro:joint_dynamics></xacro:joint_dynamics>
      </joint>
      
      <joint name="rl_coxa_to_baselink" type="revolute">
        <origin xyz="-0.091978 0.082887 0.0409" rpy="0 0 0"/>
        <parent link="base_link"/>
        <child link="rl_coxa_1"/>
        <axis xyz="0.0 0.0 -1.0"/>
        <xacro:bl_to_coxa_limits></xacro:bl_to_coxa_limits>
        <xacro:joint_dynamics></xacro:joint_dynamics>
      </joint> -->

      <joint name="rl_coxa_to_baselink" type="fixed">
  <origin xyz="-0.091978 0.082887 0.0409" rpy="0 0 0"/>
  <parent link="base_link"/>
  <child link="rl_coxa_1"/>
  <!-- <axis xyz="-0.0 0.0 -1.0"/>
  <limit upper="0.610865" lower="-0.785398" effort="100" velocity="100"/> -->
</joint>

<joint name="rl_femur_to_coxa" type="fixed">
  <origin xyz="-0.012509 0.048995 0.0185" rpy="0 0 0"/>
  <parent link="rl_coxa_1"/>
  <child link="rl_femur_1"/>
  <!-- <axis xyz="0.707107 0.707107 0.0"/>
  <limit upper="0.261799" lower="-1.396263" effort="100" velocity="100"/> -->
</joint>

<joint name="rl_tibia_to_femur" type="fixed">
  <origin xyz="1e-06 1e-06 0.08" rpy="0 0 0"/>
  <parent link="rl_femur_1"/>
  <child link="rl_tibia_1"/>
  <!-- <axis xyz="-0.707107 -0.707107 -0.0"/>
  <limit upper="0.0" lower="-2.268928" effort="100" velocity="100"/> -->
</joint>

<joint name="rl_sensor_to_tibia" type="fixed">
  <origin xyz="-0.048829 0.012342 -0.115032" rpy="0 0 0"/>
  <parent link="rl_tibia_1"/>
  <child link="rl_sensor_1"/>
</joint>

<joint name="rr_coxa_to_baselink" type="fixed">
  <origin xyz="-0.091978 -0.082887 0.0409" rpy="0 0 0"/>
  <parent link="base_link"/>
  <child link="rr_coxa_1"/><!-- 
  <axis xyz="0.0 -0.0 1.0"/>
  <limit upper="0.872665" lower="-1.047198" effort="100" velocity="100"/> -->
</joint>

<joint name="rr_femur_to_coxa" type="fixed">
  <origin xyz="-0.012509 -0.048995 0.0185" rpy="0 0 0"/>
  <parent link="rr_coxa_1"/>
  <child link="rr_femur_1"/><!-- 
  <axis xyz="0.707107 -0.707107 -0.0"/>
  <limit upper="2.094395" lower="-0.174533" effort="100" velocity="100"/> -->
</joint>

<joint name="rr_tibia_to_femur" type="fixed">
  <origin xyz="1e-06 -1e-06 0.08" rpy="0 0 0"/>
  <parent link="rr_femur_1"/>
  <child link="rr_tibia_1"/><!-- 
  <axis xyz="0.707107 -0.707107 -0.0"/>
  <limit upper="0.0" lower="-2.094395" effort="100" velocity="100"/> -->
</joint>

<joint name="rr_sensor_to_tibia" type="fixed">
  <origin xyz="-0.048829 -0.012342 -0.115032" rpy="0 0 0"/>
  <parent link="rr_tibia_1"/>
  <child link="rr_sensor_1"/>
</joint>

<joint name="fl_coxa_to_baselink" type="fixed">
  <origin xyz="0.091978 0.082887 0.0409" rpy="0 0 0"/>
  <parent link="base_link"/>
  <child link="fl_coxa_1"/><!-- 
  <axis xyz="-0.0 -0.0 1.0"/>
  <limit upper="0.872665" lower="-0.698132" effort="100" velocity="100"/> -->
</joint>

<joint name="fl_femur_to_coxa" type="fixed">
  <origin xyz="0.012509 0.048995 0.0185" rpy="0 0 0"/>
  <parent link="fl_coxa_1"/>
  <child link="fl_femur_1"/><!-- 
  <axis xyz="0.707107 -0.707107 -0.0"/>
  <limit upper="0.0" lower="-2.181662" effort="100" velocity="100"/> -->
</joint>

<joint name="fl_tibia_to_femur" type="fixed">
  <origin xyz="-1e-06 1e-06 0.08" rpy="0 0 0"/>
  <parent link="fl_femur_1"/>
  <child link="fl_tibia_1"/><!-- 
  <axis xyz="-0.707107 0.707107 0.0"/>
  <limit upper="0.0" lower="-2.094395" effort="100" velocity="100"/> -->
</joint>

<joint name="fl_sensor_to_tibia" type="fixed">
  <origin xyz="0.048829 0.012342 -0.115032" rpy="0 0 0"/>
  <parent link="fl_tibia_1"/>
  <child link="fl_sensor_1"/>
</joint>

<joint name="fr_coxa_to_baselink" type="fixed">
  <origin xyz="0.091978 -0.082887 0.0409" rpy="0 0 0"/>
  <parent link="base_link"/>
  <child link="fr_coxa_1"/><!-- 
  <axis xyz="0.0 0.0 -1.0"/>
  <limit upper="0.698132" lower="-0.523599" effort="100" velocity="100"/> -->
</joint>

<joint name="fr_femur_to_coxa" type="fixed">
  <origin xyz="0.012509 -0.048995 0.0185" rpy="0 0 0"/>
  <parent link="fr_coxa_1"/>
  <child link="fr_femur_1"/><!-- 
  <axis xyz="-0.707107 -0.707107 0.0"/>
  <limit upper="0.0" lower="-2.181662" effort="100" velocity="100"/> -->
</joint>

<joint name="fr_tibia_to_femur" type="fixed">
  <origin xyz="-1e-06 -1e-06 0.08" rpy="0 0 0"/>
  <parent link="fr_femur_1"/>
  <child link="fr_tibia_1"/><!-- 
  <axis xyz="0.707107 0.707107 -0.0"/>
  <limit upper="0.0" lower="-2.181662" effort="100" velocity="100"/> -->
</joint>

<joint name="fr_sensor_to_tibia" type="fixed">
  <origin xyz="0.048829 -0.012342 -0.115032" rpy="0 0 0"/>
  <parent link="fr_tibia_1"/>
  <child link="fr_sensor_1"/>
</joint>

</robot>